<mujoco model="partnet_26616b8217bd2ef12619db0a5cf36754">
  <option iterations="50" timestep="0.001" solver="PGS" gravity="0 0 -9.81" />

  <compiler angle="radian" eulerseq="zyx" autolimits="true" />

  <default>
    <joint limited="true" damping="0.01" armature="0.01" frictionloss="0.01" />
    <geom condim="4" contype="1" conaffinity="15" friction="0.9 0.2 0.2" solref="0.001 2" />
    <motor ctrllimited="true" />
    <equality solref="0.001 2" />
    <default class="visualgeom">
      <geom material="visualgeom" condim="1" contype="0" conaffinity="0" />
    </default>
  </default>

  <asset>
    <mesh name="link_0_convex" content_type="model/obj" file="meshes/link_0_convex.obj" />
    <mesh name="link_1_convex" content_type="model/obj" file="meshes/link_1_convex.obj" />
    <mesh name="link_2_convex" content_type="model/obj" file="meshes/link_2_convex.obj" />
    <texture name="texplane" type="2d" builtin="checker" rgb1=".0 .0 .0" rgb2=".8 .8 .8" width="100" height="100" />
    <material name="matplane" reflectance="0." texture="texplane" texrepeat="1 1" texuniform="true" />
    <material name="visualgeom" rgba="0.5 0.9 0.2 1" />
  </asset>

  <worldbody>
    <light directional="true" diffuse="0.4 0.4 0.4" specular="0.1 0.1 0.1" pos="0 0 5.0" dir="0 0 -1" castshadow="false" />
    <light directional="true" diffuse="0.6 0.6 0.6" specular="0.2 0.2 0.2" pos="0 0 4" dir="0 0 -1" />
    <geom name="ground" type="plane" pos="0 0 0" size="100 100 0.001" quat="1 0 0 0" material="matplane" condim="3" conaffinity="15" />
    <camera name="fixed" pos="0 -3.0 1.4758274886545564" xyaxes="1 0 0 0 0 1" />
    <camera name="track" mode="trackcom" pos="0 -3.0 1.4758274886545564" xyaxes="1 0 0 0 0 1" />
    <body name="root" pos="0 0 0.9758274886545564" quat="1 0 0 0">
      <freejoint name="root" />
      <site name="imu" size="0.01" pos="0 0 0" />
      <geom pos="0 0 0" quat="0.5 0.5 -0.5 -0.5" type="mesh" mesh="link_0_convex" contype="1" conaffinity="0" density="0" group="1" class="visualgeom" />
      <geom type="mesh" rgba="" mesh="link_0_convex" pos="0 0 0" quat="0.5 0.5 -0.5 -0.5" />
      <body name="link_1" pos="0.104352 -0.254289 0.823603" quat="0.5 0.5 -0.5 -0.5">
        <joint name="joint_1" pos="0 0 0" axis="0 1 0" range="-0.816814 1.50796" damping="0.0002" frictionloss="0.01" />
        <geom pos="-0.254289 -0.823603 0.104352" quat="1 0 0 0" type="mesh" mesh="link_1_convex" contype="1" conaffinity="0" density="0" group="1" class="visualgeom" />
        <geom type="mesh" rgba="" mesh="link_1_convex" pos="-0.254289 -0.823603 0.104352" quat="1 0 0 0" />
        <body name="link_2" pos="-0.439038 -1.01798 0.395463">
          <joint name="joint_2" pos="0 0 0" axis="-0.707108 1.63273e-08 -0.707106" range="-0.785398 0.785398" damping="0.0002" frictionloss="0.01" />
          <geom pos="0.184749 0.194382 -0.291111" quat="1 0 0 0" type="mesh" mesh="link_2_convex" contype="1" conaffinity="0" density="0" group="1" class="visualgeom" />
          <geom type="mesh" rgba="" mesh="link_2_convex" pos="0.184749 0.194382 -0.291111" quat="1 0 0 0" />
        </body>
      </body>
    </body>
  </worldbody>

  <actuator>
    <motor name="joint_1" joint="joint_1" ctrllimited="true" ctrlrange="-1 1" gear="1" />
    <motor name="joint_2" joint="joint_2" ctrllimited="true" ctrlrange="-1 1" gear="1" />
  </actuator>

  <sensor>
    <actuatorpos name="joint_1_p" actuator="joint_1" />
    <actuatorvel name="joint_1_v" actuator="joint_1" />
    <actuatorfrc name="joint_1_f" actuator="joint_1" noise="0.001" />
    <actuatorpos name="joint_2_p" actuator="joint_2" />
    <actuatorvel name="joint_2_v" actuator="joint_2" />
    <actuatorfrc name="joint_2_f" actuator="joint_2" noise="0.001" />
    <framequat name="orientation" objtype="site" noise="0.001" objname="imu" />
    <gyro name="angular-velocity" site="imu" noise="0.005" cutoff="34.9" />
  </sensor>
</mujoco>